<?xml version="1.0" encoding="UTF-8"?>
<testng-results skipped="0" failed="1" ignored="1" total="3" passed="1">
  <reporter-output>
  </reporter-output>
  <suite name="Default Suite" duration-ms="3063" started-at="2018-05-21T09:04:00Z" finished-at="2018-05-21T09:04:03Z">
    <groups>
    </groups>
    <test name="test" duration-ms="3063" started-at="2018-05-21T09:04:00Z" finished-at="2018-05-21T09:04:03Z">
      <class name="OtherTest">
        <test-method status="FAIL" signature="testCase2()[pri:0, instance:OtherTest@464bee09]" name="testCase2" duration-ms="3030" started-at="2018-05-21T09:04:00Z" finished-at="2018-05-21T09:04:03Z">
          <exception class="org.testng.internal.thread.ThreadTimeoutException">
            <message>
              <![CDATA[Method OtherTest.testCase2() didn't finish within the time-out 3000]]>
            </message>
            <full-stacktrace>
              <![CDATA[org.testng.internal.thread.ThreadTimeoutException: Method OtherTest.testCase2() didn't finish within the time-out 3000
at org.testng.internal.InvokeMethodRunnable.runOne(InvokeMethodRunnable.java:64)
at org.testng.internal.InvokeMethodRunnable.run(InvokeMethodRunnable.java:44)
at java.util.concurrent.Executors$RunnableAdapter.call(Executors.java:511)
at java.util.concurrent.FutureTask.run(FutureTask.java:266)
at java.util.concurrent.ThreadPoolExecutor.runWorker(ThreadPoolExecutor.java:1149)
at java.util.concurrent.ThreadPoolExecutor$Worker.run(ThreadPoolExecutor.java:624)
at java.lang.Thread.run(Thread.java:748)
]]>
            </full-stacktrace>
          </exception> <!-- org.testng.internal.thread.ThreadTimeoutException -->
          <reporter-output>
          </reporter-output>
        </test-method> <!-- testCase2 -->
        <test-method status="PASS" signature="testCase3()[pri:0, instance:OtherTest@464bee09]" name="testCase3" duration-ms="1" started-at="2018-05-21T09:04:03Z" finished-at="2018-05-21T09:04:03Z">
          <exception class="java.lang.ArithmeticException">
            <message>
              <![CDATA[/ by zero]]>
            </message>
            <full-stacktrace>
              <![CDATA[java.lang.ArithmeticException: / by zero
at OtherTest.testCase3(OtherTest.java:21)
at sun.reflect.NativeMethodAccessorImpl.invoke0(Native Method)
at sun.reflect.NativeMethodAccessorImpl.invoke(NativeMethodAccessorImpl.java:62)
at sun.reflect.DelegatingMethodAccessorImpl.invoke(DelegatingMethodAccessorImpl.java:43)
at java.lang.reflect.Method.invoke(Method.java:498)
at org.testng.internal.MethodInvocationHelper.invokeMethod(MethodInvocationHelper.java:124)
at org.testng.internal.Invoker.invokeMethod(Invoker.java:583)
at org.testng.internal.Invoker.invokeTestMethod(Invoker.java:719)
at org.testng.internal.Invoker.invokeTestMethods(Invoker.java:989)
at org.testng.internal.TestMethodWorker.invokeTestMethods(TestMethodWorker.java:125)
at org.testng.internal.TestMethodWorker.run(TestMethodWorker.java:109)
at org.testng.TestRunner.privateRun(TestRunner.java:648)
at org.testng.TestRunner.run(TestRunner.java:505)
at org.testng.SuiteRunner.runTest(SuiteRunner.java:455)
at org.testng.SuiteRunner.runSequentially(SuiteRunner.java:450)
at org.testng.SuiteRunner.privateRun(SuiteRunner.java:415)
at org.testng.SuiteRunner.run(SuiteRunner.java:364)
at org.testng.SuiteRunnerWorker.runSuite(SuiteRunnerWorker.java:52)
at org.testng.SuiteRunnerWorker.run(SuiteRunnerWorker.java:84)
at org.testng.TestNG.runSuitesSequentially(TestNG.java:1208)
at org.testng.TestNG.runSuitesLocally(TestNG.java:1137)
at org.testng.TestNG.runSuites(TestNG.java:1049)
at org.testng.TestNG.run(TestNG.java:1017)
at org.testng.IDEARemoteTestNG.run(IDEARemoteTestNG.java:72)
at org.testng.RemoteTestNGStarter.main(RemoteTestNGStarter.java:123)
]]>
            </full-stacktrace>
          </exception> <!-- java.lang.ArithmeticException -->
          <reporter-output>
          </reporter-output>
        </test-method> <!-- testCase3 -->
      </class> <!-- OtherTest -->
    </test> <!-- test -->
  </suite> <!-- Default Suite -->
</testng-results>
